import pytest
from unittest import mock

# Assuming the script is named calculator.py and the function is accessible
from calculator import main

@pytest.fixture
def mock_inputs():
    """Fixture to mock input values."""
    with mock.patch('builtins.input', side_effect=['3', '2']) as _mock:
        yield _mock

@pytest.fixture
def mock_inputs_division_by_zero():
    """Fixture to mock input values for division by zero case."""
    with mock.patch('builtins.input', side_effect=['4', '0']) as _mock:
        yield _mock

@pytest.fixture
def mock_print():
    """Fixture to mock print function."""
    with mock.patch('builtins.print') as _mock:
        yield _mock

def test_main_with_normal_case(mock_inputs, mock_print):
    """
    Test main function with normal inputs.
    """
    main()
    mock_print.assert_any_call("The sum is: 5.0")
    mock_print.assert_any_call("The difference is: 1.0")
    mock_print.assert_any_call("The product is: 6.0")
    mock_print.assert_any_call("The quotient is: 1.5")

def test_main_with_division_by_zero(mock_inputs_division_by_zero, mock_print):
    """
    Test main function when division by zero occurs.
    """
    main()
    mock_print.assert_any_call("The sum is: 4.0")
    mock_print.assert_any_call("The difference is: 4.0")
    mock_print.assert_any_call("The product is: 0.0")
    mock_print.assert_any_call("The quotient is: undefined (division by zero)")

def test_main_with_invalid_input():
    """
    Test main function with invalid input (mocking input to throw a ValueError).
    """
    with mock.patch('builtins.input', side_effect=['a', '1']):
        with pytest.raises(ValueError):
            main()

def test_main_with_partial_invalid_input():
    """
    Test main function with one valid and one invalid input.
    """
    with mock.patch('builtins.input', side_effect=['2', 'b']):
        with pytest.raises(ValueError):
            main()